[2022-03-06 04:13:55,459] {taskinstance.py:1037} INFO - Dependencies all met for <TaskInstance: spotify_dag.whole_spotify_etl manual__2022-03-06T04:12:18.950989+00:00 [queued]>
[2022-03-06 04:13:55,542] {taskinstance.py:1037} INFO - Dependencies all met for <TaskInstance: spotify_dag.whole_spotify_etl manual__2022-03-06T04:12:18.950989+00:00 [queued]>
[2022-03-06 04:13:55,543] {taskinstance.py:1243} INFO - 
--------------------------------------------------------------------------------
[2022-03-06 04:13:55,543] {taskinstance.py:1244} INFO - Starting attempt 2 of 2
[2022-03-06 04:13:55,549] {taskinstance.py:1245} INFO - 
--------------------------------------------------------------------------------
[2022-03-06 04:13:55,616] {taskinstance.py:1264} INFO - Executing <Task(PythonOperator): whole_spotify_etl> on 2022-03-06 04:12:18.950989+00:00
[2022-03-06 04:13:55,665] {standard_task_runner.py:52} INFO - Started process 399 to run task
[2022-03-06 04:13:55,699] {standard_task_runner.py:76} INFO - Running: ['***', 'tasks', 'run', 'spotify_dag', 'whole_spotify_etl', 'manual__2022-03-06T04:12:18.950989+00:00', '--job-id', '4', '--raw', '--subdir', 'DAGS_FOLDER/spotify_dag.py', '--cfg-path', '/tmp/tmpiu7invi3', '--error-file', '/tmp/tmpw11fqq48']
[2022-03-06 04:13:55,704] {standard_task_runner.py:77} INFO - Job 4: Subtask whole_spotify_etl
[2022-03-06 04:13:56,053] {logging_mixin.py:109} INFO - Running <TaskInstance: spotify_dag.whole_spotify_etl manual__2022-03-06T04:12:18.950989+00:00 [running]> on host 320d3876a6f4
[2022-03-06 04:13:56,615] {taskinstance.py:1431} INFO - Exporting the following env vars:
AIRFLOW_CTX_DAG_EMAIL=ing.jlllopezp@gmail.com
AIRFLOW_CTX_DAG_OWNER=***
AIRFLOW_CTX_DAG_ID=spotify_dag
AIRFLOW_CTX_TASK_ID=whole_spotify_etl
AIRFLOW_CTX_EXECUTION_DATE=2022-03-06T04:12:18.950989+00:00
AIRFLOW_CTX_DAG_RUN_ID=manual__2022-03-06T04:12:18.950989+00:00
[2022-03-06 04:14:01,747] {taskinstance.py:1718} ERROR - Task failed with exception
Traceback (most recent call last):
  File "/home/airflow/.local/lib/python3.7/site-packages/airflow/models/taskinstance.py", line 1334, in _run_raw_task
    self._execute_task_with_callbacks(context)
  File "/home/airflow/.local/lib/python3.7/site-packages/airflow/models/taskinstance.py", line 1460, in _execute_task_with_callbacks
    result = self._execute_task(context, self.task)
  File "/home/airflow/.local/lib/python3.7/site-packages/airflow/models/taskinstance.py", line 1516, in _execute_task
    result = execute_callable(context=context)
  File "/home/airflow/.local/lib/python3.7/site-packages/airflow/operators/python.py", line 174, in execute
    return_value = self.execute_callable()
  File "/home/airflow/.local/lib/python3.7/site-packages/airflow/operators/python.py", line 188, in execute_callable
    return self.python_callable(*self.op_args, **self.op_kwargs)
  File "/opt/airflow/dags/spotify_etl.py", line 64, in run_spotify_etl
    with open('./misc/token.txt', 'w') as file:
FileNotFoundError: [Errno 2] No such file or directory: './misc/token.txt'
[2022-03-06 04:14:02,313] {taskinstance.py:1282} INFO - Marking task as FAILED. dag_id=spotify_dag, task_id=whole_spotify_etl, execution_date=20220306T041218, start_date=20220306T041355, end_date=20220306T041402
[2022-03-06 04:14:03,413] {warnings.py:110} WARNING - /home/***/.local/lib/python3.7/site-packages/***/utils/email.py:108: PendingDeprecationWarning: Fetching SMTP credentials from configuration variables will be deprecated in a future release. Please set credentials using a connection instead.
  send_mime_email(e_from=mail_from, e_to=recipients, mime_msg=msg, conn_id=conn_id, dryrun=dryrun)

[2022-03-06 04:14:03,430] {configuration.py:381} WARNING - section/key [smtp/smtp_user] not found in config
[2022-03-06 04:14:03,438] {email.py:214} INFO - Email alerting: attempt 1
[2022-03-06 04:14:03,759] {configuration.py:381} WARNING - section/key [smtp/smtp_user] not found in config
[2022-03-06 04:14:03,768] {email.py:214} INFO - Email alerting: attempt 1
[2022-03-06 04:14:03,786] {taskinstance.py:1769} ERROR - Failed to send email to: ['ing.jlllopezp@gmail.com']
Traceback (most recent call last):
  File "/home/airflow/.local/lib/python3.7/site-packages/airflow/models/taskinstance.py", line 1334, in _run_raw_task
    self._execute_task_with_callbacks(context)
  File "/home/airflow/.local/lib/python3.7/site-packages/airflow/models/taskinstance.py", line 1460, in _execute_task_with_callbacks
    result = self._execute_task(context, self.task)
  File "/home/airflow/.local/lib/python3.7/site-packages/airflow/models/taskinstance.py", line 1516, in _execute_task
    result = execute_callable(context=context)
  File "/home/airflow/.local/lib/python3.7/site-packages/airflow/operators/python.py", line 174, in execute
    return_value = self.execute_callable()
  File "/home/airflow/.local/lib/python3.7/site-packages/airflow/operators/python.py", line 188, in execute_callable
    return self.python_callable(*self.op_args, **self.op_kwargs)
  File "/opt/airflow/dags/spotify_etl.py", line 64, in run_spotify_etl
    with open('./misc/token.txt', 'w') as file:
FileNotFoundError: [Errno 2] No such file or directory: './misc/token.txt'

During handling of the above exception, another exception occurred:

Traceback (most recent call last):
  File "/home/airflow/.local/lib/python3.7/site-packages/airflow/models/taskinstance.py", line 2103, in email_alert
    send_email(self.task.email, subject, html_content)
  File "/home/airflow/.local/lib/python3.7/site-packages/airflow/utils/email.py", line 69, in send_email
    **kwargs,
  File "/home/airflow/.local/lib/python3.7/site-packages/airflow/utils/email.py", line 108, in send_email_smtp
    send_mime_email(e_from=mail_from, e_to=recipients, mime_msg=msg, conn_id=conn_id, dryrun=dryrun)
  File "/home/airflow/.local/lib/python3.7/site-packages/airflow/utils/email.py", line 216, in send_mime_email
    conn = _get_smtp_connection(smtp_host, smtp_port, smtp_timeout, smtp_ssl)
  File "/home/airflow/.local/lib/python3.7/site-packages/airflow/utils/email.py", line 250, in _get_smtp_connection
    else smtplib.SMTP(host=host, port=port, timeout=timeout)
  File "/usr/local/lib/python3.7/smtplib.py", line 251, in __init__
    (code, msg) = self.connect(host, port)
  File "/usr/local/lib/python3.7/smtplib.py", line 336, in connect
    self.sock = self._get_socket(host, port, self.timeout)
  File "/usr/local/lib/python3.7/smtplib.py", line 307, in _get_socket
    self.source_address)
  File "/usr/local/lib/python3.7/socket.py", line 728, in create_connection
    raise err
  File "/usr/local/lib/python3.7/socket.py", line 716, in create_connection
    sock.connect(sa)
OSError: [Errno 99] Cannot assign requested address

During handling of the above exception, another exception occurred:

Traceback (most recent call last):
  File "/home/airflow/.local/lib/python3.7/site-packages/airflow/models/taskinstance.py", line 1767, in handle_failure
    self.email_alert(error)
  File "/home/airflow/.local/lib/python3.7/site-packages/airflow/models/taskinstance.py", line 2105, in email_alert
    send_email(self.task.email, subject, html_content_err)
  File "/home/airflow/.local/lib/python3.7/site-packages/airflow/utils/email.py", line 69, in send_email
    **kwargs,
  File "/home/airflow/.local/lib/python3.7/site-packages/airflow/utils/email.py", line 108, in send_email_smtp
    send_mime_email(e_from=mail_from, e_to=recipients, mime_msg=msg, conn_id=conn_id, dryrun=dryrun)
  File "/home/airflow/.local/lib/python3.7/site-packages/airflow/utils/email.py", line 216, in send_mime_email
    conn = _get_smtp_connection(smtp_host, smtp_port, smtp_timeout, smtp_ssl)
  File "/home/airflow/.local/lib/python3.7/site-packages/airflow/utils/email.py", line 250, in _get_smtp_connection
    else smtplib.SMTP(host=host, port=port, timeout=timeout)
  File "/usr/local/lib/python3.7/smtplib.py", line 251, in __init__
    (code, msg) = self.connect(host, port)
  File "/usr/local/lib/python3.7/smtplib.py", line 336, in connect
    self.sock = self._get_socket(host, port, self.timeout)
  File "/usr/local/lib/python3.7/smtplib.py", line 307, in _get_socket
    self.source_address)
  File "/usr/local/lib/python3.7/socket.py", line 728, in create_connection
    raise err
  File "/usr/local/lib/python3.7/socket.py", line 716, in create_connection
    sock.connect(sa)
OSError: [Errno 99] Cannot assign requested address
[2022-03-06 04:14:04,761] {standard_task_runner.py:92} ERROR - Failed to execute job 4 for task whole_spotify_etl
Traceback (most recent call last):
  File "/home/airflow/.local/lib/python3.7/site-packages/airflow/task/task_runner/standard_task_runner.py", line 85, in _start_by_fork
    args.func(args, dag=self.dag)
  File "/home/airflow/.local/lib/python3.7/site-packages/airflow/cli/cli_parser.py", line 48, in command
    return func(*args, **kwargs)
  File "/home/airflow/.local/lib/python3.7/site-packages/airflow/utils/cli.py", line 92, in wrapper
    return f(*args, **kwargs)
  File "/home/airflow/.local/lib/python3.7/site-packages/airflow/cli/commands/task_command.py", line 298, in task_run
    _run_task_by_selected_method(args, dag, ti)
  File "/home/airflow/.local/lib/python3.7/site-packages/airflow/cli/commands/task_command.py", line 107, in _run_task_by_selected_method
    _run_raw_task(args, ti)
  File "/home/airflow/.local/lib/python3.7/site-packages/airflow/cli/commands/task_command.py", line 184, in _run_raw_task
    error_file=args.error_file,
  File "/home/airflow/.local/lib/python3.7/site-packages/airflow/utils/session.py", line 70, in wrapper
    return func(*args, session=session, **kwargs)
  File "/home/airflow/.local/lib/python3.7/site-packages/airflow/models/taskinstance.py", line 1334, in _run_raw_task
    self._execute_task_with_callbacks(context)
  File "/home/airflow/.local/lib/python3.7/site-packages/airflow/models/taskinstance.py", line 1460, in _execute_task_with_callbacks
    result = self._execute_task(context, self.task)
  File "/home/airflow/.local/lib/python3.7/site-packages/airflow/models/taskinstance.py", line 1516, in _execute_task
    result = execute_callable(context=context)
  File "/home/airflow/.local/lib/python3.7/site-packages/airflow/operators/python.py", line 174, in execute
    return_value = self.execute_callable()
  File "/home/airflow/.local/lib/python3.7/site-packages/airflow/operators/python.py", line 188, in execute_callable
    return self.python_callable(*self.op_args, **self.op_kwargs)
  File "/opt/airflow/dags/spotify_etl.py", line 64, in run_spotify_etl
    with open('./misc/token.txt', 'w') as file:
FileNotFoundError: [Errno 2] No such file or directory: './misc/token.txt'
[2022-03-06 04:14:05,075] {local_task_job.py:154} INFO - Task exited with return code 1
[2022-03-06 04:14:06,094] {local_task_job.py:264} INFO - 0 downstream tasks scheduled from follow-on schedule check
