[2022-03-06 05:39:28,708] {taskinstance.py:1037} INFO - Dependencies all met for <TaskInstance: spotify_dag.whole_spotify_etl manual__2022-03-06T05:39:23.298203+00:00 [queued]>
[2022-03-06 05:39:28,817] {taskinstance.py:1037} INFO - Dependencies all met for <TaskInstance: spotify_dag.whole_spotify_etl manual__2022-03-06T05:39:23.298203+00:00 [queued]>
[2022-03-06 05:39:28,818] {taskinstance.py:1243} INFO - 
--------------------------------------------------------------------------------
[2022-03-06 05:39:28,820] {taskinstance.py:1244} INFO - Starting attempt 1 of 2
[2022-03-06 05:39:28,821] {taskinstance.py:1245} INFO - 
--------------------------------------------------------------------------------
[2022-03-06 05:39:28,949] {taskinstance.py:1264} INFO - Executing <Task(PythonOperator): whole_spotify_etl> on 2022-03-06 05:39:23.298203+00:00
[2022-03-06 05:39:29,024] {standard_task_runner.py:52} INFO - Started process 433 to run task
[2022-03-06 05:39:29,073] {standard_task_runner.py:76} INFO - Running: ['***', 'tasks', 'run', 'spotify_dag', 'whole_spotify_etl', 'manual__2022-03-06T05:39:23.298203+00:00', '--job-id', '21', '--raw', '--subdir', 'DAGS_FOLDER/spotify_dag.py', '--cfg-path', '/tmp/tmpybv66tb5', '--error-file', '/tmp/tmple19owli']
[2022-03-06 05:39:29,075] {standard_task_runner.py:77} INFO - Job 21: Subtask whole_spotify_etl
[2022-03-06 05:39:29,641] {logging_mixin.py:109} INFO - Running <TaskInstance: spotify_dag.whole_spotify_etl manual__2022-03-06T05:39:23.298203+00:00 [running]> on host 320d3876a6f4
[2022-03-06 05:39:30,161] {taskinstance.py:1431} INFO - Exporting the following env vars:
AIRFLOW_CTX_DAG_EMAIL=ing.jlllopezp@gmail.com
AIRFLOW_CTX_DAG_OWNER=***
AIRFLOW_CTX_DAG_ID=spotify_dag
AIRFLOW_CTX_TASK_ID=whole_spotify_etl
AIRFLOW_CTX_EXECUTION_DATE=2022-03-06T05:39:23.298203+00:00
AIRFLOW_CTX_DAG_RUN_ID=manual__2022-03-06T05:39:23.298203+00:00
[2022-03-06 05:39:38,219] {logging_mixin.py:109} INFO - here goes a new token
[2022-03-06 05:39:42,705] {logging_mixin.py:109} INFO - here goes a new token
[2022-03-06 05:39:45,134] {logging_mixin.py:109} INFO - here goes a new token
[2022-03-06 05:39:49,042] {logging_mixin.py:109} INFO - here goes a new token
[2022-03-06 05:39:54,866] {logging_mixin.py:109} INFO - here goes a new token
[2022-03-06 05:40:01,317] {logging_mixin.py:109} INFO - here goes a new token
[2022-03-06 05:40:06,422] {logging_mixin.py:109} INFO - here goes a new token
[2022-03-06 05:40:13,563] {logging_mixin.py:109} INFO - here goes a new token
[2022-03-06 05:40:18,992] {logging_mixin.py:109} INFO - here goes a new token
[2022-03-06 05:40:22,973] {logging_mixin.py:109} INFO - here goes a new token
[2022-03-06 05:40:25,967] {logging_mixin.py:109} INFO - here goes a new token
[2022-03-06 05:40:29,051] {logging_mixin.py:109} INFO - here goes a new token
[2022-03-06 05:40:33,407] {logging_mixin.py:109} INFO - here goes a new token
[2022-03-06 05:40:36,342] {logging_mixin.py:109} INFO - here goes a new token
[2022-03-06 05:40:39,467] {logging_mixin.py:109} INFO - here goes a new token
[2022-03-06 05:40:41,949] {logging_mixin.py:109} INFO - here goes a new token
[2022-03-06 05:40:44,161] {logging_mixin.py:109} INFO - here goes a new token
[2022-03-06 05:40:47,027] {logging_mixin.py:109} INFO - here goes a new token
[2022-03-06 05:40:49,999] {logging_mixin.py:109} INFO - here goes a new token
[2022-03-06 05:40:57,770] {logging_mixin.py:109} INFO - here goes a new token
[2022-03-06 05:41:05,624] {logging_mixin.py:109} INFO - here goes a new token
[2022-03-06 05:41:10,243] {logging_mixin.py:109} INFO - here goes a new token
[2022-03-06 05:41:25,071] {logging_mixin.py:109} INFO - here goes a new token
[2022-03-06 05:41:32,462] {logging_mixin.py:109} INFO - here goes a new token
[2022-03-06 05:41:37,597] {logging_mixin.py:109} INFO - here goes a new token
[2022-03-06 05:41:43,360] {logging_mixin.py:109} INFO - here goes a new token
[2022-03-06 05:41:56,908] {logging_mixin.py:109} INFO - here goes a new token
[2022-03-06 05:42:59,133] {logging_mixin.py:109} INFO - here goes a new token
[2022-03-06 05:43:07,347] {logging_mixin.py:109} INFO - here goes a new token
[2022-03-06 05:43:20,038] {logging_mixin.py:109} INFO - here goes a new token
[2022-03-06 05:45:04,991] {taskinstance.py:1718} ERROR - Task failed with exception
Traceback (most recent call last):
  File "/home/airflow/.local/lib/python3.7/site-packages/urllib3/connectionpool.py", line 710, in urlopen
    chunked=chunked,
  File "/home/airflow/.local/lib/python3.7/site-packages/urllib3/connectionpool.py", line 386, in _make_request
    self._validate_conn(conn)
  File "/home/airflow/.local/lib/python3.7/site-packages/urllib3/connectionpool.py", line 1040, in _validate_conn
    conn.connect()
  File "/home/airflow/.local/lib/python3.7/site-packages/urllib3/connection.py", line 426, in connect
    tls_in_tls=tls_in_tls,
  File "/home/airflow/.local/lib/python3.7/site-packages/urllib3/util/ssl_.py", line 450, in ssl_wrap_socket
    sock, context, tls_in_tls, server_hostname=server_hostname
  File "/home/airflow/.local/lib/python3.7/site-packages/urllib3/util/ssl_.py", line 493, in _ssl_wrap_socket_impl
    return ssl_context.wrap_socket(sock, server_hostname=server_hostname)
  File "/usr/local/lib/python3.7/ssl.py", line 423, in wrap_socket
    session=session
  File "/usr/local/lib/python3.7/ssl.py", line 870, in _create
    self.do_handshake()
  File "/usr/local/lib/python3.7/ssl.py", line 1139, in do_handshake
    self._sslobj.do_handshake()
ConnectionResetError: [Errno 104] Connection reset by peer

During handling of the above exception, another exception occurred:

Traceback (most recent call last):
  File "/home/airflow/.local/lib/python3.7/site-packages/requests/adapters.py", line 450, in send
    timeout=timeout
  File "/home/airflow/.local/lib/python3.7/site-packages/urllib3/connectionpool.py", line 786, in urlopen
    method, url, error=e, _pool=self, _stacktrace=sys.exc_info()[2]
  File "/home/airflow/.local/lib/python3.7/site-packages/urllib3/util/retry.py", line 550, in increment
    raise six.reraise(type(error), error, _stacktrace)
  File "/home/airflow/.local/lib/python3.7/site-packages/urllib3/packages/six.py", line 769, in reraise
    raise value.with_traceback(tb)
  File "/home/airflow/.local/lib/python3.7/site-packages/urllib3/connectionpool.py", line 710, in urlopen
    chunked=chunked,
  File "/home/airflow/.local/lib/python3.7/site-packages/urllib3/connectionpool.py", line 386, in _make_request
    self._validate_conn(conn)
  File "/home/airflow/.local/lib/python3.7/site-packages/urllib3/connectionpool.py", line 1040, in _validate_conn
    conn.connect()
  File "/home/airflow/.local/lib/python3.7/site-packages/urllib3/connection.py", line 426, in connect
    tls_in_tls=tls_in_tls,
  File "/home/airflow/.local/lib/python3.7/site-packages/urllib3/util/ssl_.py", line 450, in ssl_wrap_socket
    sock, context, tls_in_tls, server_hostname=server_hostname
  File "/home/airflow/.local/lib/python3.7/site-packages/urllib3/util/ssl_.py", line 493, in _ssl_wrap_socket_impl
    return ssl_context.wrap_socket(sock, server_hostname=server_hostname)
  File "/usr/local/lib/python3.7/ssl.py", line 423, in wrap_socket
    session=session
  File "/usr/local/lib/python3.7/ssl.py", line 870, in _create
    self.do_handshake()
  File "/usr/local/lib/python3.7/ssl.py", line 1139, in do_handshake
    self._sslobj.do_handshake()
urllib3.exceptions.ProtocolError: ('Connection aborted.', ConnectionResetError(104, 'Connection reset by peer'))

During handling of the above exception, another exception occurred:

Traceback (most recent call last):
  File "/home/airflow/.local/lib/python3.7/site-packages/airflow/models/taskinstance.py", line 1334, in _run_raw_task
    self._execute_task_with_callbacks(context)
  File "/home/airflow/.local/lib/python3.7/site-packages/airflow/models/taskinstance.py", line 1460, in _execute_task_with_callbacks
    result = self._execute_task(context, self.task)
  File "/home/airflow/.local/lib/python3.7/site-packages/airflow/models/taskinstance.py", line 1516, in _execute_task
    result = execute_callable(context=context)
  File "/home/airflow/.local/lib/python3.7/site-packages/airflow/operators/python.py", line 174, in execute
    return_value = self.execute_callable()
  File "/home/airflow/.local/lib/python3.7/site-packages/airflow/operators/python.py", line 188, in execute_callable
    return self.python_callable(*self.op_args, **self.op_kwargs)
  File "/opt/airflow/dags/spotify_etl.py", line 59, in run_spotify_etl
    time=before_unix_timestamp), headers=headers)
  File "/home/airflow/.local/lib/python3.7/site-packages/requests/api.py", line 75, in get
    return request('get', url, params=params, **kwargs)
  File "/home/airflow/.local/lib/python3.7/site-packages/requests/api.py", line 61, in request
    return session.request(method=method, url=url, **kwargs)
  File "/home/airflow/.local/lib/python3.7/site-packages/requests/sessions.py", line 529, in request
    resp = self.send(prep, **send_kwargs)
  File "/home/airflow/.local/lib/python3.7/site-packages/requests/sessions.py", line 645, in send
    r = adapter.send(request, **kwargs)
  File "/home/airflow/.local/lib/python3.7/site-packages/requests/adapters.py", line 501, in send
    raise ConnectionError(err, request=request)
requests.exceptions.ConnectionError: ('Connection aborted.', ConnectionResetError(104, 'Connection reset by peer'))
[2022-03-06 05:45:05,074] {taskinstance.py:1282} INFO - Marking task as UP_FOR_RETRY. dag_id=spotify_dag, task_id=whole_spotify_etl, execution_date=20220306T053923, start_date=20220306T053928, end_date=20220306T054505
[2022-03-06 05:45:05,168] {standard_task_runner.py:92} ERROR - Failed to execute job 21 for task whole_spotify_etl
Traceback (most recent call last):
  File "/home/airflow/.local/lib/python3.7/site-packages/urllib3/connectionpool.py", line 710, in urlopen
    chunked=chunked,
  File "/home/airflow/.local/lib/python3.7/site-packages/urllib3/connectionpool.py", line 386, in _make_request
    self._validate_conn(conn)
  File "/home/airflow/.local/lib/python3.7/site-packages/urllib3/connectionpool.py", line 1040, in _validate_conn
    conn.connect()
  File "/home/airflow/.local/lib/python3.7/site-packages/urllib3/connection.py", line 426, in connect
    tls_in_tls=tls_in_tls,
  File "/home/airflow/.local/lib/python3.7/site-packages/urllib3/util/ssl_.py", line 450, in ssl_wrap_socket
    sock, context, tls_in_tls, server_hostname=server_hostname
  File "/home/airflow/.local/lib/python3.7/site-packages/urllib3/util/ssl_.py", line 493, in _ssl_wrap_socket_impl
    return ssl_context.wrap_socket(sock, server_hostname=server_hostname)
  File "/usr/local/lib/python3.7/ssl.py", line 423, in wrap_socket
    session=session
  File "/usr/local/lib/python3.7/ssl.py", line 870, in _create
    self.do_handshake()
  File "/usr/local/lib/python3.7/ssl.py", line 1139, in do_handshake
    self._sslobj.do_handshake()
ConnectionResetError: [Errno 104] Connection reset by peer

During handling of the above exception, another exception occurred:

Traceback (most recent call last):
  File "/home/airflow/.local/lib/python3.7/site-packages/requests/adapters.py", line 450, in send
    timeout=timeout
  File "/home/airflow/.local/lib/python3.7/site-packages/urllib3/connectionpool.py", line 786, in urlopen
    method, url, error=e, _pool=self, _stacktrace=sys.exc_info()[2]
  File "/home/airflow/.local/lib/python3.7/site-packages/urllib3/util/retry.py", line 550, in increment
    raise six.reraise(type(error), error, _stacktrace)
  File "/home/airflow/.local/lib/python3.7/site-packages/urllib3/packages/six.py", line 769, in reraise
    raise value.with_traceback(tb)
  File "/home/airflow/.local/lib/python3.7/site-packages/urllib3/connectionpool.py", line 710, in urlopen
    chunked=chunked,
  File "/home/airflow/.local/lib/python3.7/site-packages/urllib3/connectionpool.py", line 386, in _make_request
    self._validate_conn(conn)
  File "/home/airflow/.local/lib/python3.7/site-packages/urllib3/connectionpool.py", line 1040, in _validate_conn
    conn.connect()
  File "/home/airflow/.local/lib/python3.7/site-packages/urllib3/connection.py", line 426, in connect
    tls_in_tls=tls_in_tls,
  File "/home/airflow/.local/lib/python3.7/site-packages/urllib3/util/ssl_.py", line 450, in ssl_wrap_socket
    sock, context, tls_in_tls, server_hostname=server_hostname
  File "/home/airflow/.local/lib/python3.7/site-packages/urllib3/util/ssl_.py", line 493, in _ssl_wrap_socket_impl
    return ssl_context.wrap_socket(sock, server_hostname=server_hostname)
  File "/usr/local/lib/python3.7/ssl.py", line 423, in wrap_socket
    session=session
  File "/usr/local/lib/python3.7/ssl.py", line 870, in _create
    self.do_handshake()
  File "/usr/local/lib/python3.7/ssl.py", line 1139, in do_handshake
    self._sslobj.do_handshake()
urllib3.exceptions.ProtocolError: ('Connection aborted.', ConnectionResetError(104, 'Connection reset by peer'))

During handling of the above exception, another exception occurred:

Traceback (most recent call last):
  File "/home/airflow/.local/lib/python3.7/site-packages/airflow/task/task_runner/standard_task_runner.py", line 85, in _start_by_fork
    args.func(args, dag=self.dag)
  File "/home/airflow/.local/lib/python3.7/site-packages/airflow/cli/cli_parser.py", line 48, in command
    return func(*args, **kwargs)
  File "/home/airflow/.local/lib/python3.7/site-packages/airflow/utils/cli.py", line 92, in wrapper
    return f(*args, **kwargs)
  File "/home/airflow/.local/lib/python3.7/site-packages/airflow/cli/commands/task_command.py", line 298, in task_run
    _run_task_by_selected_method(args, dag, ti)
  File "/home/airflow/.local/lib/python3.7/site-packages/airflow/cli/commands/task_command.py", line 107, in _run_task_by_selected_method
    _run_raw_task(args, ti)
  File "/home/airflow/.local/lib/python3.7/site-packages/airflow/cli/commands/task_command.py", line 184, in _run_raw_task
    error_file=args.error_file,
  File "/home/airflow/.local/lib/python3.7/site-packages/airflow/utils/session.py", line 70, in wrapper
    return func(*args, session=session, **kwargs)
  File "/home/airflow/.local/lib/python3.7/site-packages/airflow/models/taskinstance.py", line 1334, in _run_raw_task
    self._execute_task_with_callbacks(context)
  File "/home/airflow/.local/lib/python3.7/site-packages/airflow/models/taskinstance.py", line 1460, in _execute_task_with_callbacks
    result = self._execute_task(context, self.task)
  File "/home/airflow/.local/lib/python3.7/site-packages/airflow/models/taskinstance.py", line 1516, in _execute_task
    result = execute_callable(context=context)
  File "/home/airflow/.local/lib/python3.7/site-packages/airflow/operators/python.py", line 174, in execute
    return_value = self.execute_callable()
  File "/home/airflow/.local/lib/python3.7/site-packages/airflow/operators/python.py", line 188, in execute_callable
    return self.python_callable(*self.op_args, **self.op_kwargs)
  File "/opt/airflow/dags/spotify_etl.py", line 59, in run_spotify_etl
    time=before_unix_timestamp), headers=headers)
  File "/home/airflow/.local/lib/python3.7/site-packages/requests/api.py", line 75, in get
    return request('get', url, params=params, **kwargs)
  File "/home/airflow/.local/lib/python3.7/site-packages/requests/api.py", line 61, in request
    return session.request(method=method, url=url, **kwargs)
  File "/home/airflow/.local/lib/python3.7/site-packages/requests/sessions.py", line 529, in request
    resp = self.send(prep, **send_kwargs)
  File "/home/airflow/.local/lib/python3.7/site-packages/requests/sessions.py", line 645, in send
    r = adapter.send(request, **kwargs)
  File "/home/airflow/.local/lib/python3.7/site-packages/requests/adapters.py", line 501, in send
    raise ConnectionError(err, request=request)
requests.exceptions.ConnectionError: ('Connection aborted.', ConnectionResetError(104, 'Connection reset by peer'))
[2022-03-06 05:45:05,257] {local_task_job.py:154} INFO - Task exited with return code 1
[2022-03-06 05:45:05,755] {local_task_job.py:264} INFO - 0 downstream tasks scheduled from follow-on schedule check
